Traceback (most recent call last):
  File "C:\Users\achma\AppData\Roaming\Python\Python310\site-packages\jupyter_core\utils\__init__.py", line 154, in wrapped
    asyncio.get_running_loop()
RuntimeError: no running event loop

During handling of the above exception, another exception occurred:

Traceback (most recent call last):
  File "C:\laragon\bin\python\python-3.10\lib\site-packages\jupyter_cache\executors\utils.py", line 58, in single_nb_execution
    executenb(
  File "C:\laragon\bin\python\python-3.10\lib\site-packages\nbclient\client.py", line 1319, in execute
    return NotebookClient(nb=nb, resources=resources, km=km, **kwargs).execute()
  File "C:\Users\achma\AppData\Roaming\Python\Python310\site-packages\jupyter_core\utils\__init__.py", line 158, in wrapped
    return loop.run_until_complete(inner)
  File "C:\laragon\bin\python\python-3.10\lib\asyncio\base_events.py", line 646, in run_until_complete
    return future.result()
  File "C:\laragon\bin\python\python-3.10\lib\site-packages\nbclient\client.py", line 709, in async_execute
    await self.async_execute_cell(
  File "C:\laragon\bin\python\python-3.10\lib\site-packages\nbclient\client.py", line 1062, in async_execute_cell
    await self._check_raise_for_error(cell, cell_index, exec_reply)
  File "C:\laragon\bin\python\python-3.10\lib\site-packages\nbclient\client.py", line 918, in _check_raise_for_error
    raise CellExecutionError.from_cell_and_msg(cell, exec_reply_content)
nbclient.exceptions.CellExecutionError: An error occurred while executing the following cell:
------------------
# Load data
def load_data():
    if MYSQL_OK:
        try:
            engine = create_engine("mysql+pymysql://root:@localhost/ecoli")
            query = "SELECT protein_name, mcg, gvh, lip, chg, aac, alm1, alm2, localization_class FROM protein_localization"
            df = pd.read_sql(query, engine)
            print(f"Data loaded from MySQL: {df.shape}")
            return df
        except Exception as e:
            print(f"MySQL failed: {e}")
    

df = load_data()
print(f"Dataset shape: {df.shape}")
print(f"Classes: {sorted(df['localization_class'].unique())}")
display(df.head())
------------------

----- stdout -----
MySQL failed: (pymysql.err.OperationalError) (2003, "Can't connect to MySQL server on 'localhost' ([WinError 10061] No connection could be made because the target machine actively refused it)")
(Background on this error at: https://sqlalche.me/e/20/e3q8)
------------------

[1;31m---------------------------------------------------------------------------[0m
[1;31mAttributeError[0m                            Traceback (most recent call last)
Cell [1;32mIn[3], line 15[0m
[0;32m     11[0m             [38;5;28mprint[39m([38;5;124mf[39m[38;5;124m"[39m[38;5;124mMySQL failed: [39m[38;5;132;01m{[39;00me[38;5;132;01m}[39;00m[38;5;124m"[39m)
[0;32m     14[0m df [38;5;241m=[39m load_data()
[1;32m---> 15[0m [38;5;28mprint[39m([38;5;124mf[39m[38;5;124m"[39m[38;5;124mDataset shape: [39m[38;5;132;01m{[39;00m[43mdf[49m[38;5;241;43m.[39;49m[43mshape[49m[38;5;132;01m}[39;00m[38;5;124m"[39m)
[0;32m     16[0m [38;5;28mprint[39m([38;5;124mf[39m[38;5;124m"[39m[38;5;124mClasses: [39m[38;5;132;01m{[39;00m[38;5;28msorted[39m(df[[38;5;124m'[39m[38;5;124mlocalization_class[39m[38;5;124m'[39m][38;5;241m.[39munique())[38;5;132;01m}[39;00m[38;5;124m"[39m)
[0;32m     17[0m display(df[38;5;241m.[39mhead())

[1;31mAttributeError[0m: 'NoneType' object has no attribute 'shape'

