Traceback (most recent call last):
  File "C:\Users\achma\AppData\Roaming\Python\Python310\site-packages\jupyter_core\utils\__init__.py", line 154, in wrapped
    asyncio.get_running_loop()
RuntimeError: no running event loop

During handling of the above exception, another exception occurred:

Traceback (most recent call last):
  File "C:\laragon\bin\python\python-3.10\lib\site-packages\jupyter_cache\executors\utils.py", line 58, in single_nb_execution
    executenb(
  File "C:\laragon\bin\python\python-3.10\lib\site-packages\nbclient\client.py", line 1319, in execute
    return NotebookClient(nb=nb, resources=resources, km=km, **kwargs).execute()
  File "C:\Users\achma\AppData\Roaming\Python\Python310\site-packages\jupyter_core\utils\__init__.py", line 158, in wrapped
    return loop.run_until_complete(inner)
  File "C:\laragon\bin\python\python-3.10\lib\asyncio\base_events.py", line 646, in run_until_complete
    return future.result()
  File "C:\laragon\bin\python\python-3.10\lib\site-packages\nbclient\client.py", line 709, in async_execute
    await self.async_execute_cell(
  File "C:\laragon\bin\python\python-3.10\lib\site-packages\nbclient\client.py", line 1062, in async_execute_cell
    await self._check_raise_for_error(cell, cell_index, exec_reply)
  File "C:\laragon\bin\python\python-3.10\lib\site-packages\nbclient\client.py", line 918, in _check_raise_for_error
    raise CellExecutionError.from_cell_and_msg(cell, exec_reply_content)
nbclient.exceptions.CellExecutionError: An error occurred while executing the following cell:
------------------
# Statistik per spesies
print("=== STATISTIK DESKRIPTIF PER SPESIES ===")
for species in df['species'].unique():
    print(f"\nğŸ“Š Spesies: {species.upper()}")
    species_data = df[df['species'] == species][features]
    print(species_data.describe().round(2))
------------------

----- stdout -----
=== STATISTIK DESKRIPTIF PER SPESIES ===
------------------

[1;31m---------------------------------------------------------------------------[0m
[1;31mAttributeError[0m                            Traceback (most recent call last)
Cell [1;32mIn[18], line 4[0m
[0;32m      2[0m [38;5;28mprint[39m([38;5;124m"[39m[38;5;124m=== STATISTIK DESKRIPTIF PER SPESIES ===[39m[38;5;124m"[39m)
[0;32m      3[0m [38;5;28;01mfor[39;00m species [38;5;129;01min[39;00m df[[38;5;124m'[39m[38;5;124mspecies[39m[38;5;124m'[39m][38;5;241m.[39munique():
[1;32m----> 4[0m     [38;5;28mprint[39m([38;5;124mf[39m[38;5;124m"[39m[38;5;130;01m\n[39;00m[38;5;124mğŸ“Š Spesies: [39m[38;5;132;01m{[39;00m[43mspecies[49m[38;5;241;43m.[39;49m[43mupper[49m()[38;5;132;01m}[39;00m[38;5;124m"[39m)
[0;32m      5[0m     species_data [38;5;241m=[39m df[df[[38;5;124m'[39m[38;5;124mspecies[39m[38;5;124m'[39m] [38;5;241m==[39m species][features]
[0;32m      6[0m     [38;5;28mprint[39m(species_data[38;5;241m.[39mdescribe()[38;5;241m.[39mround([38;5;241m2[39m))

[1;31mAttributeError[0m: 'numpy.int64' object has no attribute 'upper'

